{
 "cells": [
  {
   "cell_type": "code",
   "execution_count": null,
   "metadata": {
    "nbsphinx": "hidden",
    "outputs_hidden": true,
    "source_hidden": true
   },
   "outputs": [],
   "source": [
    "import inspect\n",
    "from unittest import mock\n",
    "\n",
    "orig_stack = inspect.stack\n",
    "base_skip = len(inspect.stack()) - 1\n",
    "\n",
    "\n",
    "def stack():\n",
    "    return orig_stack()[1:-base_skip]\n",
    "\n",
    "\n",
    "inspect.stack = stack\n",
    "\n",
    "with mock.patch(\"seqtools.errors.inspect\", inspect):\n",
    "    import seqtools"
   ]
  },
  {
   "cell_type": "markdown",
   "metadata": {},
   "source": [
    "# Error handling and debuging\n",
    "\n",
    "During the design of a transformation pipeline, mistakes and programming errors are relatively frequent.\n",
    "SeqTools tries to recover from them and report useful informations as much as possible.\n",
    "This tutorial reviews some details about the internal error management and should facilitate your debugging sessions.\n",
    "\n",
    "\n",
    "## Tracing mapping errors\n",
    "\n",
    "Due to on-demand execution, an error generated by mapping a function to an item won't raise when the mapping is created but rather when the problematic element is read."
   ]
  },
  {
   "cell_type": "code",
   "execution_count": null,
   "metadata": {
    "run_control": {
     "marked": true
    }
   },
   "outputs": [],
   "source": [
    "import math\n",
    "import seqtools\n",
    "\n",
    "\n",
    "def f1(x):\n",
    "    return math.sqrt(x)  # this will fail for negative values\n",
    "\n",
    "\n",
    "data = [0, 4, 6, 7, 2, 4, 4, -1]  # sqrt(-1) raises ValueError\n",
    "out = seqtools.smap(f1, data)"
   ]
  },
  {
   "cell_type": "markdown",
   "metadata": {},
   "source": [
    "Due to on-demand execution, no error is raised yet for the last item.\n",
    "\n",
    "As soon as it is evaluated, SeqTools raises an `EvaluationError` and sets the original exception as its cause."
   ]
  },
  {
   "cell_type": "code",
   "execution_count": null,
   "metadata": {
    "run_control": {
     "marked": true
    }
   },
   "outputs": [],
   "source": [
    "list(out)"
   ]
  },
  {
   "cell_type": "markdown",
   "metadata": {},
   "source": [
    "The `ValueError` that caused the failure is detailed first.\n",
    "\n",
    "The `EvaluationError` message provides additional clarification: it tells which item caused the error and where the mapping was defined, a crucial debugging information when the mapping function is used at multiple locations in the code.\n",
    "\n",
    "If you prefer working with the original exception directly and skip the `EvaluationError` wrapper, you can enable the _'passthrough'_ error mode which does just that:"
   ]
  },
  {
   "cell_type": "code",
   "execution_count": null,
   "metadata": {},
   "outputs": [],
   "source": [
    "seqtools.seterr(evaluation=\"passthrough\")\n",
    "\n",
    "list(out)"
   ]
  },
  {
   "cell_type": "code",
   "execution_count": null,
   "metadata": {},
   "outputs": [],
   "source": [
    "seqtools.seterr(evaluation=\"wrap\")  # revert to normal behaviour"
   ]
  },
  {
   "cell_type": "markdown",
   "metadata": {},
   "source": [
    "## Errors inside worker\n",
    "\n",
    "Background workers used by `prefetch` do not share the execution space of the main program and exceptions raised while evaluating elements will happen asynchronously.\n",
    "\n",
    "To facilitate troubleshooting, SeqTools silently stores exception data, sends it back to the main process to be re-raised when failed items are read.\n",
    "In practice it looks like exceptions happen when the items are read."
   ]
  },
  {
   "cell_type": "code",
   "execution_count": null,
   "metadata": {},
   "outputs": [],
   "source": [
    "out = seqtools.smap(f1, data)\n",
    "out = seqtools.prefetch(out, max_buffered=10)\n",
    "\n",
    "# evaluate all elements but the last\n",
    "for i in range(len(out) - 1):\n",
    "    out[i]\n",
    "\n",
    "# evaluate the final one\n",
    "out[-1]"
   ]
  },
  {
   "cell_type": "markdown",
   "metadata": {},
   "source": [
    "Note that the workers will continue processing other items just fine after an error.\n",
    "\n",
    "Transfering exceptions back to the parent process has some notable limitations:\n",
    "\n",
    "- Process-based workers cannot save errors that cannot be pickled, in particular exception types defined inside a function. These will be replaced by an text message.\n",
    "- Error tracebacks cannot be completely serialized so debuggers won't be able to explore the whole error context."
   ]
  }
 ],
 "metadata": {
  "celltoolbar": "Edit Metadata",
  "kernelspec": {
   "display_name": "Python 3",
   "language": "python",
   "name": "python3"
  },
  "language_info": {
   "codemirror_mode": {
    "name": "ipython",
    "version": 3
   },
   "file_extension": ".py",
   "mimetype": "text/x-python",
   "name": "python",
   "nbconvert_exporter": "python",
   "pygments_lexer": "ipython3",
   "version": "3.11.3"
  }
 },
 "nbformat": 4,
 "nbformat_minor": 4
}
